<?xml version="1.0"?>
<robot xmlns:xacro="http://wiki.ros.org/xacro" name="kr3r540">


  <xacro:arg name="is_sim" default="true"/>

<xacro:include filename="kr3r540_gazebo.xacro"/>
<xacro:include filename="kr3r540_ros2_control.xacro"/>
 <link name="world">
</link>

<link name="base_link">
  <visual>
    <geometry>
      <mesh filename="package://kr3r540_description/meshes/visual/base_link.stl"/>
    </geometry>
    <material name="kuka_pedestal">
      <color rgba="0.50588 0.47059 0.38824 1.0"/>
    </material>
  </visual>
  <collision>
    <geometry>
      <mesh filename="package://kr3r540_description/meshes/collision/base_link.stl"/>
    </geometry>
  </collision>
  <inertial>
    <origin xyz="0 0 0" rpy="0 0 0"/>
    <mass value="11.37"/>
    <inertia ixx="0.537" ixy="0.002" ixz="0.014" iyy="0.804" iyz="0.00" izz="0.745"/>
  </inertial>
</link>

<link name="link_1">
  <visual>
    <geometry>
      <mesh filename="package://kr3r540_description/meshes/visual/link_1.stl"/>
    </geometry>
    <material name="kuka_ral_pure_white">
      <color rgba="1.0 1.0 1.0 1.0"/>
    </material>
  </visual>
  <collision>
    <geometry>
      <mesh filename="package://kr3r540_description/meshes/collision/link_1.stl"/>
    </geometry>
  </collision>
  <inertial>
    <origin xyz="0 0 0" rpy="0 0 0"/>
    <mass value="7"/>
    <inertia ixx="0.361" ixy="-0.001" ixz="-0.0014" iyy="0.255" iyz="-0.007" izz="0.29"/>
  </inertial>
</link> 

<link name="link_2">
  <visual>
    <geometry>
      <mesh filename="package://kr3r540_description/meshes/visual/link_2.stl"/>
    </geometry>
    <material name="kuka_ral_pure_white">
      <color rgba="1.0 1.0 1.0 1.0"/>
    </material>
  </visual>
  <collision>
    <geometry>
      <mesh filename="package://kr3r540_description/meshes/collision/link_2.stl"/>
    </geometry>
  </collision>
  <inertial>
    <origin xyz="0 0 0" rpy="0 0 0"/>
    <mass value="6.9"/>
    <inertia ixx="0.249" ixy="-0.007" ixz="-0.021" iyy="0.573" iyz="-0.001" izz="0.708"/>
  </inertial>
</link>

<link name="link_3">
  <visual>
    <geometry>
      <mesh filename="package://kr3r540_description/meshes/visual/link_3.stl"/>
    </geometry>
    <material name="kuka_ral_pure_white">
      <color rgba="1.0 1.0 1.0 1.0"/>
    </material>
  </visual>
  <collision>
    <geometry>
      <mesh filename="package://kr3r540_description/meshes/collision/link_3.stl"/>
    </geometry>
  </collision>
  <inertial>
    <origin xyz="0 0 0" rpy="0 0 0"/>
    <mass value="3"/>
    <inertia ixx="0.005464170195346057" ixy="2.317865761359266e-05" ixz="-0.0008376172568479034"
            iyy="0.009668497673794239" iyz="-5.3812765981131285e-06" izz="0.009530838326239676"/>
</inertial>
</link>

<link name="link_4">
  <visual>
    <geometry>
      <mesh filename="package://kr3r540_description/meshes/visual/link_4.stl"/>
    </geometry>
    <material name="kuka_ral_pure_white">
      <color rgba="1.0 1.0 1.0 1.0"/>
    </material>
  </visual>
  <collision>
    <geometry>
      <mesh filename="package://kr3r540_description/meshes/collision/link_4.stl"/>
    </geometry>
  </collision>
  <inertial>
    <origin xyz="0 0 0" rpy="0 0 0"/>
    <mass value="2"/>
    <inertia ixx="0.04" ixy="-0.004" ixz="0.00" iyy="0.045" iyz="-0.001" izz="0.063"/>
  </inertial>
</link>

<link name="link_5">
  <visual>
    <geometry>
      <mesh filename="package://kr3r540_description/meshes/visual/link_5.stl"/>
    </geometry>
    <material name="kuka_ral_pure_white">
      <color rgba="1.0 1.0 1.0 1.0"/>
    </material>
  </visual>
  <collision>
    <geometry>
      <mesh filename="package://kr3r540_description/meshes/collision/link_5.stl"/>
    </geometry>
  </collision>
  <inertial>
    <origin xyz="0 0 0" rpy="0 0 0"/>
    <mass value="1"/>
    <inertia ixx="0.0009523921025026232" ixy="-1.4859377039896955e-05" ixz="-2.6599547296907754e-07"
            iyy="0.001277581091791774" iyz="2.9443366764204974e-07" izz="0.0014178861490860182"/>
</inertial>
</link>

<link name="link_6">
  <visual>
    <geometry>
      <mesh filename="package://kr3r540_description/meshes/visual/link_6.stl"/>
    </geometry>
    <material name="kuka_pedestal">
      <color rgba="0.50588 0.47059 0.38824 1.0"/>
    </material>
  </visual>
  <collision>
    <geometry>
      <mesh filename="package://kr3r540_description/meshes/collision/link_6.stl"/>
    </geometry>
  </collision>
  <inertial>
    <origin xyz="0 0 0" rpy="0 0 0"/>
    <mass value="0.03"/>
    <inertia ixx="9.7510332695528e-06" ixy="-5.535554975934552e-11" ixz="1.0491860620923319e-16"
            iyy="5.458075446678377e-06" iyz="-3.0083248575603903e-19" izz="5.45822894382603e-06"/>
</inertial>
</link>

<link name="greifer">
  <visual>
    <geometry>
      <mesh filename="package://kr3r540_description/meshes/visual/greifer.stl" scale="0.1 0.1 0.1"/>
    </geometry>
    <material name="kuka_black">
      <color rgba="0.0549 0.0549 0.0627 1.0"/>
    </material>
  </visual>
  <collision>
    <geometry>
      <mesh filename="package://kr3r540_description/meshes/collision/greifer.stl" scale="0.1 0.1 0.1"/>
    </geometry>
  </collision>
  <inertial>
    <origin xyz="0 0 0" rpy="0 0 0"/>
    <mass value="0.19"/>
    <inertia ixx="13.106" ixy="-0.034" ixz="0.083" iyy="14.078" iyz="0.17" izz="4.086"/>
  </inertial>
</link>

<!-- Define Joints -->

<joint name="world_to_base" type="fixed">
  <parent link="world"/>
  <child link="base_link"/>
  <origin xyz="0 0 0" rpy="0 0 0"/>
</joint>

<joint name="joint_1" type="revolute">
  <parent link="base_link"/>
  <child link="link_1"/>
  <origin xyz="0 0 0.345" rpy="0 0 0"/>
  <axis xyz="0 0 -1"/>
  <limit lower="-2.967" upper="2.967" effort="1000" velocity="9.266"/>
</joint>

<joint name="joint_2" type="revolute">
  <parent link="link_1"/>
  <child link="link_2"/>
  <origin xyz="0.020 0 0" rpy="0 0 0"/>
  <axis xyz="0 1 0"/>
  <limit lower="-2.967" upper="0.872665" effort="1000" velocity="9.233"/>
</joint>

<joint name="joint_3" type="revolute">
  <parent link="link_2"/>
  <child link="link_3"/>
  <origin xyz="0.260 0 0" rpy="0 0 0"/>
  <axis xyz="0 1 0"/>
  <limit lower="-1.919" upper="2.705" effort="1000" velocity="9.389"/>
</joint>

<joint name="joint_4" type="revolute">
  <parent link="link_3"/>
  <child link="link_4"/>
  <origin xyz="0 0 0.020" rpy="0 0 0"/>
  <axis xyz="-1 0 0"/>
  <limit lower="-3.054" upper="3.054" effort="1000" velocity="10.472"/>
</joint>

<joint name="joint_5" type="revolute">
  <parent link="link_4"/>
  <child link="link_5"/>
   <origin xyz="0.260 0 0" rpy="0 0 0"/>
  <axis xyz="0 1 0"/>
  <limit lower="-2.094" upper="2.094" effort="1000" velocity="10.472"/>
</joint>

<joint name="joint_6" type="revolute">
  <parent link="link_5"/>
  <child link="link_6"/>
  <origin xyz="0.075 0 0" rpy="0 0 0"/>
  <axis xyz="-1 0 0"/>
  <limit lower="-6.108" upper="6.108" effort="1000" velocity="13.962"/>
</joint>

<joint name="flange" type="fixed">
  <parent link="link_6"/>
  <child link="greifer"/>
  <origin xyz="0.032 0 -0.02" rpy="0 0 1.5708"/>
</joint>

 
</robot>